{"trial_id": "00", "hyperparameters": {"space": [{"class_name": "Int", "config": {"name": "filters", "default": null, "conditions": [], "min_value": 32, "max_value": 256, "step": 32, "sampling": "linear"}}, {"class_name": "Choice", "config": {"name": "kernel_size", "default": 3, "conditions": [], "values": [3, 5], "ordered": true}}, {"class_name": "Float", "config": {"name": "learning_rate", "default": 0.0001, "conditions": [], "min_value": 0.0001, "max_value": 0.01, "step": null, "sampling": "log"}}], "values": {"filters": 160, "kernel_size": 5, "learning_rate": 0.0020221562707338596}}, "metrics": {"metrics": {}}, "score": null, "best_step": 0, "status": "FAILED", "message": "Traceback (most recent call last):\n  File \"C:\\Users\\02221\\.conda\\envs\\ml_course1\\lib\\site-packages\\keras_tuner\\src\\engine\\base_tuner.py\", line 274, in _try_run_and_update_trial\n    self._run_and_update_trial(trial, *fit_args, **fit_kwargs)\n  File \"C:\\Users\\02221\\.conda\\envs\\ml_course1\\lib\\site-packages\\keras_tuner\\src\\engine\\base_tuner.py\", line 239, in _run_and_update_trial\n    results = self.run_trial(trial, *fit_args, **fit_kwargs)\n  File \"C:\\Users\\02221\\.conda\\envs\\ml_course1\\lib\\site-packages\\keras_tuner\\src\\engine\\tuner.py\", line 314, in run_trial\n    obj_value = self._build_and_fit_model(trial, *args, **copied_kwargs)\n  File \"C:\\Users\\02221\\.conda\\envs\\ml_course1\\lib\\site-packages\\keras_tuner\\src\\engine\\tuner.py\", line 233, in _build_and_fit_model\n    results = self.hypermodel.fit(hp, model, *args, **kwargs)\n  File \"C:\\Users\\02221\\.conda\\envs\\ml_course1\\lib\\site-packages\\keras_tuner\\src\\engine\\hypermodel.py\", line 149, in fit\n    return model.fit(*args, **kwargs)\n  File \"C:\\Users\\02221\\.conda\\envs\\ml_course1\\lib\\site-packages\\keras\\utils\\traceback_utils.py\", line 70, in error_handler\n    raise e.with_traceback(filtered_tb) from None\n  File \"C:\\Users\\02221\\.conda\\envs\\ml_course1\\lib\\site-packages\\tensorflow\\python\\eager\\execute.py\", line 54, in quick_execute\n    tensors = pywrap_tfe.TFE_Py_Execute(ctx._handle, device_name, op_name,\ntensorflow.python.framework.errors_impl.InvalidArgumentError: Graph execution error:\n\nDetected at node 'mean_squared_error/SquaredDifference' defined at (most recent call last):\n    File \"C:\\Users\\02221\\.conda\\envs\\ml_course1\\lib\\runpy.py\", line 196, in _run_module_as_main\n      return _run_code(code, main_globals, None,\n    File \"C:\\Users\\02221\\.conda\\envs\\ml_course1\\lib\\runpy.py\", line 86, in _run_code\n      exec(code, run_globals)\n    File \"C:\\Users\\02221\\.conda\\envs\\ml_course1\\lib\\site-packages\\ipykernel_launcher.py\", line 17, in <module>\n      app.launch_new_instance()\n    File \"C:\\Users\\02221\\.conda\\envs\\ml_course1\\lib\\site-packages\\traitlets\\config\\application.py\", line 992, in launch_instance\n      app.start()\n    File \"C:\\Users\\02221\\.conda\\envs\\ml_course1\\lib\\site-packages\\ipykernel\\kernelapp.py\", line 736, in start\n      self.io_loop.start()\n    File \"C:\\Users\\02221\\.conda\\envs\\ml_course1\\lib\\site-packages\\tornado\\platform\\asyncio.py\", line 195, in start\n      self.asyncio_loop.run_forever()\n    File \"C:\\Users\\02221\\.conda\\envs\\ml_course1\\lib\\asyncio\\base_events.py\", line 603, in run_forever\n      self._run_once()\n    File \"C:\\Users\\02221\\.conda\\envs\\ml_course1\\lib\\asyncio\\base_events.py\", line 1909, in _run_once\n      handle._run()\n    File \"C:\\Users\\02221\\.conda\\envs\\ml_course1\\lib\\asyncio\\events.py\", line 80, in _run\n      self._context.run(self._callback, *self._args)\n    File \"C:\\Users\\02221\\.conda\\envs\\ml_course1\\lib\\site-packages\\ipykernel\\kernelbase.py\", line 516, in dispatch_queue\n      await self.process_one()\n    File \"C:\\Users\\02221\\.conda\\envs\\ml_course1\\lib\\site-packages\\ipykernel\\kernelbase.py\", line 505, in process_one\n      await dispatch(*args)\n    File \"C:\\Users\\02221\\.conda\\envs\\ml_course1\\lib\\site-packages\\ipykernel\\kernelbase.py\", line 412, in dispatch_shell\n      await result\n    File \"C:\\Users\\02221\\.conda\\envs\\ml_course1\\lib\\site-packages\\ipykernel\\kernelbase.py\", line 740, in execute_request\n      reply_content = await reply_content\n    File \"C:\\Users\\02221\\.conda\\envs\\ml_course1\\lib\\site-packages\\ipykernel\\ipkernel.py\", line 422, in do_execute\n      res = shell.run_cell(\n    File \"C:\\Users\\02221\\.conda\\envs\\ml_course1\\lib\\site-packages\\ipykernel\\zmqshell.py\", line 546, in run_cell\n      return super().run_cell(*args, **kwargs)\n    File \"C:\\Users\\02221\\.conda\\envs\\ml_course1\\lib\\site-packages\\IPython\\core\\interactiveshell.py\", line 3024, in run_cell\n      result = self._run_cell(\n    File \"C:\\Users\\02221\\.conda\\envs\\ml_course1\\lib\\site-packages\\IPython\\core\\interactiveshell.py\", line 3079, in _run_cell\n      result = runner(coro)\n    File \"C:\\Users\\02221\\.conda\\envs\\ml_course1\\lib\\site-packages\\IPython\\core\\async_helpers.py\", line 129, in _pseudo_sync_runner\n      coro.send(None)\n    File \"C:\\Users\\02221\\.conda\\envs\\ml_course1\\lib\\site-packages\\IPython\\core\\interactiveshell.py\", line 3284, in run_cell_async\n      has_raised = await self.run_ast_nodes(code_ast.body, cell_name,\n    File \"C:\\Users\\02221\\.conda\\envs\\ml_course1\\lib\\site-packages\\IPython\\core\\interactiveshell.py\", line 3466, in run_ast_nodes\n      if await self.run_code(code, result, async_=asy):\n    File \"C:\\Users\\02221\\.conda\\envs\\ml_course1\\lib\\site-packages\\IPython\\core\\interactiveshell.py\", line 3526, in run_code\n      exec(code_obj, self.user_global_ns, self.user_ns)\n    File \"C:\\Users\\02221\\AppData\\Local\\Temp\\ipykernel_2296\\770839611.py\", line 26, in <module>\n      tuner.search(X_train_1, y_train_1, epochs=10, validation_data=(X_test_1, y_test_1))\n    File \"C:\\Users\\02221\\.conda\\envs\\ml_course1\\lib\\site-packages\\keras_tuner\\src\\engine\\base_tuner.py\", line 234, in search\n      self._try_run_and_update_trial(trial, *fit_args, **fit_kwargs)\n    File \"C:\\Users\\02221\\.conda\\envs\\ml_course1\\lib\\site-packages\\keras_tuner\\src\\engine\\base_tuner.py\", line 274, in _try_run_and_update_trial\n      self._run_and_update_trial(trial, *fit_args, **fit_kwargs)\n    File \"C:\\Users\\02221\\.conda\\envs\\ml_course1\\lib\\site-packages\\keras_tuner\\src\\engine\\base_tuner.py\", line 239, in _run_and_update_trial\n      results = self.run_trial(trial, *fit_args, **fit_kwargs)\n    File \"C:\\Users\\02221\\.conda\\envs\\ml_course1\\lib\\site-packages\\keras_tuner\\src\\engine\\tuner.py\", line 314, in run_trial\n      obj_value = self._build_and_fit_model(trial, *args, **copied_kwargs)\n    File \"C:\\Users\\02221\\.conda\\envs\\ml_course1\\lib\\site-packages\\keras_tuner\\src\\engine\\tuner.py\", line 233, in _build_and_fit_model\n      results = self.hypermodel.fit(hp, model, *args, **kwargs)\n    File \"C:\\Users\\02221\\.conda\\envs\\ml_course1\\lib\\site-packages\\keras_tuner\\src\\engine\\hypermodel.py\", line 149, in fit\n      return model.fit(*args, **kwargs)\n    File \"C:\\Users\\02221\\.conda\\envs\\ml_course1\\lib\\site-packages\\keras\\utils\\traceback_utils.py\", line 65, in error_handler\n      return fn(*args, **kwargs)\n    File \"C:\\Users\\02221\\.conda\\envs\\ml_course1\\lib\\site-packages\\keras\\engine\\training.py\", line 1564, in fit\n      tmp_logs = self.train_function(iterator)\n    File \"C:\\Users\\02221\\.conda\\envs\\ml_course1\\lib\\site-packages\\keras\\engine\\training.py\", line 1160, in train_function\n      return step_function(self, iterator)\n    File \"C:\\Users\\02221\\.conda\\envs\\ml_course1\\lib\\site-packages\\keras\\engine\\training.py\", line 1146, in step_function\n      outputs = model.distribute_strategy.run(run_step, args=(data,))\n    File \"C:\\Users\\02221\\.conda\\envs\\ml_course1\\lib\\site-packages\\keras\\engine\\training.py\", line 1135, in run_step\n      outputs = model.train_step(data)\n    File \"C:\\Users\\02221\\.conda\\envs\\ml_course1\\lib\\site-packages\\keras\\engine\\training.py\", line 994, in train_step\n      loss = self.compute_loss(x, y, y_pred, sample_weight)\n    File \"C:\\Users\\02221\\.conda\\envs\\ml_course1\\lib\\site-packages\\keras\\engine\\training.py\", line 1052, in compute_loss\n      return self.compiled_loss(\n    File \"C:\\Users\\02221\\.conda\\envs\\ml_course1\\lib\\site-packages\\keras\\engine\\compile_utils.py\", line 265, in __call__\n      loss_value = loss_obj(y_t, y_p, sample_weight=sw)\n    File \"C:\\Users\\02221\\.conda\\envs\\ml_course1\\lib\\site-packages\\keras\\losses.py\", line 152, in __call__\n      losses = call_fn(y_true, y_pred)\n    File \"C:\\Users\\02221\\.conda\\envs\\ml_course1\\lib\\site-packages\\keras\\losses.py\", line 272, in call\n      return ag_fn(y_true, y_pred, **self._fn_kwargs)\n    File \"C:\\Users\\02221\\.conda\\envs\\ml_course1\\lib\\site-packages\\keras\\losses.py\", line 1486, in mean_squared_error\n      return backend.mean(tf.math.squared_difference(y_pred, y_true), axis=-1)\nNode: 'mean_squared_error/SquaredDifference'\nIncompatible shapes: [32,1] vs. [32,44,160]\n\t [[{{node mean_squared_error/SquaredDifference}}]] [Op:__inference_train_function_47966]\n"}